Workbook
Name AREAland.C: [1]input!$L$287
Name AREAland.R: [1]input!$L$259
Name AREAsea.C: [1]input!$L$288
Name AREAsea.R: [1]input!$L$260
Name DEPTHfreshwater.C: [1]input!$L$300
Name DEPTHfreshwater.R: [1]input!$L$270
Name DEPTHlake.C: [1]input!$L$299
Name DEPTHlake.R: [1]input!$L$269
Name FRACagsoil.C: [1]input!$L$294
Name FRACfresh.C: [1]input!$L$292
Name FRAClake.C: [1]input!$L$291
Name FRACnatsoil.C: [1]input!$L$293
Name FRACothersoil.C: [1]input!$L$295
Name période_sélectionnée: [2]Echéancier!$H$2
Name PériodeDansPlan: [2]Echéancier!A$5=MEDIAN([2]Echéancier!A$5,[2]Echéancier!$C1,[2]Echéancier!$C1+[2]Echéancier!$D1-1)
Name PériodeDansRéel: [2]Echéancier!A$5=MEDIAN([2]Echéancier!A$5,[2]Echéancier!$E1,[2]Echéancier!$E1+[2]Echéancier!$F1-1)
Name Plan: PériodeDansPlan*([2]Echéancier!$C1>0)
Name PourcentageAccompli: PourcentageAccompliAuDelà*PériodeDansPlan
Name Réel: (PériodeDansRéel*([2]Echéancier!$E1>0))*PériodeDansPlan
Name RéelAuDelà: PériodeDansRéel*([2]Echéancier!$E1>0)
Name RegionBaseRowNr: [3]Run!$F$10
Name SYSTEMAREA.C: [1]continental!$L$16
Name SYSTEMAREA.R: [1]regional!$L$16

Sheet description
B3: SUPPORTING INFORMATION FOR:
B5: Saadi, N., Hajjar, C., Ospital, L., Quik, J., Corella-Puertas, E., Hids, A., Lebrun, M., Louvet, J., Tang, Y., Thonemann, N., Boulay, A.-M. (under review). MarILCA Characterization Factors for Microplastics, Tire Particles and Cellulosic Fibers in Life Cycle Assessment : Regionalized impacts in marine, freshwater and terrestrial ecosystems.
B9: Description:
B10: Supplementary information with derivation of input data for SimpleBox object-oriented (SBoo): degradation data, landscape data, UV intensity calculations, exposure and effect factors (EEFs), Species richness distribution.
B14: Table of content | D14: Description
B15: 1. Degradation data | D15: - Specific surface degradation rates (SSDRs) obtained in literature or derived in previous studies, per compartment and per polymer. A range of values is given to reprsent the full range of degradation rate data available, used in the uncertainty analysis. - PlasticFADE degradation model data given in Tang & Boulay (under reivew). SimpleBox uses these inputs by default, if available for a specific polymer.
C16: 1.1. SSDRs for water compartments
C17: 1.2. SSDRs for sediment compartments
C18: 1.3. SSDRs for soil compartments
C19: 1.4. PlasticFADE constants
B20: 2. Transfer rates in the marine environment | D20: Default sedimentation rates are input when SBoo returns a settling velocity of 0 m/s (for particles with density lower than that of water). However, for the marine environment, these default settling velocities are not used, as TrackMPD is used to derive settling velocities from water surface to water column, from water column to sediments, at continental and global scales. These settling velocities can be found here.
C21: 2.1. Default sedimentation rates for low density polymers
C22: 2.2. TrackMPD results
B23: 3. SimpleBox object-oriented input | D23: SimpleBox directly reads these sheets to retrive data for fate factors and characterization factors calculations. The sheet contains regional landscape data (e.g. rainrate, wind speed, depth of compartments), polymer data (e.g. degradation rates, density), TrackMPD transfer rates, exposure and effect data (in water, soil, and sediments), and confidence intervals (distribution) when available.
C24: 3.1. Regional landscape data
C25: 3.2. Polymer data
C26: 3.3. Polymer data for uncertainty analysis
C27: 3.4. Exposure and effect factors per compartment with their distribution
C28: 3.5. TrackMPD transfer rates between marine compartments
B29: 4.1. Aggregation data | D29: - Data used to derive the percentage of species in marine environments, for each continent and the global scale (IUCN). - GEP values per continent, per ecosystem used for GLAM compatible units. - Data on emissions to the environment, per polymer type. The ratio of emissions is used for polymer emission-weighted average CFs.
C30: 4.1. Marine species richness data
C31: 4.2. Global exctinction probability (GEP)
C32: 4.3. Polymer emissions data for default CFs
B33: 5. USEtox data | D33: USEtox HC20s for water, used to compare to the HC20 of microplastics. Only used to generate graphs. Data taken from Douziech et al. (2024).
C34: 5.1. Effect factors
C35: 5.2. Characterization factors
B36: References | D36: References to the data used in each sheet.

Sheet 1.1.SSDR_water
B2: SSDR water
B4: SSDR values are taken from Louvet et al. (2026), Saadi et al. (2025), Saadi & Boulay (2026), and Corella-Puertas et al. (2023). SBoo requires [m/s] as an input for Kssdr. It is assumed that SSDRs are log-normally distributed (Corella-Puertas et al., 2023), and that the lower to upper limit represents the 99% confidence interval (CI), from which the distribution parameters are derived and used as an input in SBoo (for probabilistic solver). However, when plasticFADE model empirical degradation constants (and their CI) are available, they are used as input to compute degradation rates, ignoring the values below.
I5: log-normal distribution | J5: z_0.995 = | K5: 2.576
B6: Polymer type | C6: Geometric mean SSDR [µm/year] | D6: Lower limit SSDR [µm/year] | E6: Upper limit SSDR [µm/year] | F6: Geometric mean SSDR [m/s] | G6: Lower limit SSDR [m/s] | H6: Upper limit SSDR [m/s] | I6: mu | J6: sigma
B7: EPS | C7: =GEOMEAN(D7,E7) -> 0.031622777 | D7: 0.001 | E7: 1 | F7: =GEOMEAN(G7:H7) -> 1.0027517e-15 | G7: =(D7*0.000001)/(365*24*3600) -> 3.1709792e-17 | H7: =(E7*0.000001)/(365*24*3600) -> 3.1709792e-14 | I7: =LN(F7) -> -34.536029 | J7: =(LN(H7)-LN(G7))/(2*$K$5) -> 1.340791
B8: HDPE | C8: =GEOMEAN(D8,E8) -> 0.10954451 | D8: 0.001 | E8: 12 | F8: =GEOMEAN(G8:H8) -> 3.4736337e-15 | G8: =(D8*0.000001)/(365*24*3600) -> 3.1709792e-17 | H8: =(E8*0.000001)/(365*24*3600) -> 3.805175e-13 | I8: =LN(F8) -> -33.293575 | J8: =(LN(H8)-LN(G8))/(2*$K$5) -> 1.8231098
B9: LDPE | C9: =GEOMEAN(D9,E9) -> 0.19498718 | D9: 0.001 | E9: 38.02 | F9: =GEOMEAN(G9:H9) -> 6.1830029e-15 | G9: =(D9*0.000001)/(365*24*3600) -> 3.1709792e-17 | H9: =(E9*0.000001)/(365*24*3600) -> 1.2056063e-12 | I9: =LN(F9) -> -32.716972 | J9: =(LN(H9)-LN(G9))/(2*$K$5) -> 2.0469464
B10: PA_Nylon | C10: =GEOMEAN(D10,E10) -> 3.2 | D10: 0.032 | E10: 320 | F10: =GEOMEAN(G10:H10) -> 1.0147133e-13 | G10: =(D10*0.000001)/(365*24*3600) -> 1.0147133e-15 | H10: =(E10*0.000001)/(365*24*3600) -> 1.0147133e-11 | I10: =LN(F10) -> -29.919 | J10: =(LN(H10)-LN(G10))/(2*$K$5) -> 1.7877213
B11: PET | C11: =GEOMEAN(D11,E11) -> 0.32403703 | D11: 0.001 | E11: 105 | F11: =GEOMEAN(G11:H11) -> 1.0275147e-14 | G11: =(D11*0.000001)/(365*24*3600) -> 3.1709792e-17 | H11: =(E11*0.000001)/(365*24*3600) -> 3.3295282e-12 | I11: =LN(F11) -> -32.209048 | J11: =(LN(H11)-LN(G11))/(2*$K$5) -> 2.2441218
B12: PP | C12: =GEOMEAN(D12,E12) -> 1.2328828 | D12: 0.2 | E12: 7.6 | F12: =GEOMEAN(G12:H12) -> 3.9094457e-14 | G12: =(D12*0.000001)/(365*24*3600) -> 6.3419584e-15 | H12: =(E12*0.000001)/(365*24*3600) -> 2.4099442e-13 | I12: =LN(F12) -> -30.872796 | J12: =(LN(H12)-LN(G12))/(2*$K$5) -> 0.70605321
B13: PS | C13: =GEOMEAN(D13,E13) -> 0.031622777 | D13: 0.001 | E13: 1 | F13: =GEOMEAN(G13:H13) -> 1.0027517e-15 | G13: =(D13*0.000001)/(365*24*3600) -> 3.1709792e-17 | H13: =(E13*0.000001)/(365*24*3600) -> 3.1709792e-14 | I13: =LN(F13) -> -34.536029 | J13: =(LN(H13)-LN(G13))/(2*$K$5) -> 1.340791
B14: PVC | C14: =GEOMEAN(D14,E14) -> 0.01 | D14: 0.001 | E14: 0.1 | F14: =GEOMEAN(G14:H14) -> 3.1709792e-16 | G14: =(D14*0.000001)/(365*24*3600) -> 3.1709792e-17 | H14: =(E14*0.000001)/(365*24*3600) -> 3.1709792e-15 | I14: =LN(F14) -> -35.687321 | J14: =(LN(H14)-LN(G14))/(2*$K$5) -> 0.89386067
B15: PU | C15: =GEOMEAN(D15,E15) -> 0.25248762 | D15: 0.001 | E15: 63.75 | F15: =GEOMEAN(G15:H15) -> 8.00633e-15 | G15: =(D15*0.000001)/(365*24*3600) -> 3.1709792e-17 | H15: =(E15*0.000001)/(365*24*3600) -> 2.0214992e-12 | I15: =LN(F15) -> -32.458544 | J15: =(LN(H15)-LN(G15))/(2*$K$5) -> 2.1472679
B16: PAN | C16: =GEOMEAN(D16,E16) -> 0.01 | D16: 0.001 | E16: 0.1 | F16: =GEOMEAN(G16:H16) -> 3.1709792e-16 | G16: =(D16*0.000001)/(365*24*3600) -> 3.1709792e-17 | H16: =(E16*0.000001)/(365*24*3600) -> 3.1709792e-15 | I16: =LN(F16) -> -35.687321 | J16: =(LN(H16)-LN(G16))/(2*$K$5) -> 0.89386067
B17: TRWP | C17: - | D17: - | E17: - | F17: =GEOMEAN(G17:H17) -> 3.3287916e-15 | G17: 3.16881e-17 | H17: 3.49685e-13 | I17: =LN(F17) -> -33.336167 | J17: =(LN(H17)-LN(G17))/(2*$K$5) -> 1.8068414
B18: PHA | C18: =GEOMEAN(D18,E18) -> 112.62327 | D18: 7.55 | E18: 1680 | F18: =GEOMEAN(G18:H18) -> 3.5712603e-12 | G18: =(D18*0.000001)/(365*24*3600) -> 2.3940893e-13 | H18: =(E18*0.000001)/(365*24*3600) -> 5.3272451e-11 | I18: =LN(F18) -> -26.358103 | J18: =(LN(H18)-LN(G18))/(2*$K$5) -> 1.0491074
B19: PLA | C19: =GEOMEAN(D19,E19) -> 0.08660254 | D19: 0.001 | E19: 7.5 | F19: =GEOMEAN(G19:H19) -> 2.7461485e-15 | G19: =(D19*0.000001)/(365*24*3600) -> 3.1709792e-17 | H19: =(E19*0.000001)/(365*24*3600) -> 2.3782344e-13 | I19: =LN(F19) -> -33.528577 | J19: =(LN(H19)-LN(G19))/(2*$K$5) -> 1.7318824
B20: PCL | C20: =GEOMEAN(D20,E20) -> 14.839903 | D20: 1.31416 | E20: 167.5768 | F20: =GEOMEAN(G20:H20) -> 4.7057024e-13 | G20: =(D20*0.000001)/(365*24*3600) -> 4.167174e-14 | H20: =(E20*0.000001)/(365*24*3600) -> 5.3138255e-12 | I20: =LN(F20) -> -28.384831 | J20: =(LN(H20)-LN(G20))/(2*$K$5) -> 0.94104116
B21: PBSA | C21: =GEOMEAN(D21,E21) -> 1.5655184 | D21: 0.608 | E21: 4.031 | F21: =GEOMEAN(G21:H21) -> 4.9642264e-14 | G21: =(D21*0.000001)/(365*24*3600) -> 1.9279554e-14 | H21: =(E21*0.000001)/(365*24*3600) -> 1.2782217e-13 | I21: =LN(F21) -> -30.633934 | J21: =(LN(H21)-LN(G21))/(2*$K$5) -> 0.36715739
B22: starch_blend | C22: 101.29 | D22: =C22/10 -> 10.129 | E22: =C22*10 -> 1012.9 | F22: =GEOMEAN(G22:H22) -> 3.2118848e-12 | G22: =(D22*0.000001)/(365*24*3600) -> 3.2118848e-13 | H22: =(E22*0.000001)/(365*24*3600) -> 3.2118848e-11 | I22: =LN(F22) -> -26.464163 | J22: =(LN(H22)-LN(G22))/(2*$K$5) -> 0.89386067
B23: PBAT | C23: =GEOMEAN(D23,E23) -> 11.752936 | D23: 10.27 | E23: 13.45 | F23: =GEOMEAN(G23:H23) -> 3.7268315e-13 | G23: =(D23*0.000001)/(365*24*3600) -> 3.2565956e-13 | H23: =(E23*0.000001)/(365*24*3600) -> 4.264967e-13 | I23: =LN(F23) -> -28.618048 | J23: =(LN(H23)-LN(G23))/(2*$K$5) -> 0.052358712
B24: Cotton | C24: =GEOMEAN(D24,E24) -> 18.300786 | D24: 5.9971847 | E24: 55.845997 | F24: =GEOMEAN(G24:H24) -> 5.8031411e-13 | G24: =(D24*0.000001)/(365*24*3600) -> 1.9016948e-13 | H24: =(E24*0.000001)/(365*24*3600) -> 1.770865e-12 | I24: =LN(F24) -> -28.175207 | J24: =(LN(H24)-LN(G24))/(2*$K$5) -> 0.43309544
B25: Linen | C25: =GEOMEAN(D25,E25) -> 32.689902 | D25: 21.74 | E25: 49.155 | F25: =GEOMEAN(G25:H25) -> 1.03659e-12 | G25: =(D25*0.000001)/(365*24*3600) -> 6.8937088e-13 | H25: =(E25*0.000001)/(365*24*3600) -> 1.5586948e-12 | I25: =LN(F25) -> -27.595085 | J25: =(LN(H25)-LN(G25))/(2*$K$5) -> 0.15835107
B26: Viscose | C26: =GEOMEAN(D26,E26) -> 24.559331 | D26: 21.922321 | E26: 27.513544 | F26: =GEOMEAN(G26:H26) -> 7.7877128e-13 | G26: =(D26*0.000001)/(365*24*3600) -> 6.9515223e-13 | H26: =(E26*0.000001)/(365*24*3600) -> 8.7244877e-13 | I26: =LN(F26) -> -27.881059 | J26: =(LN(H26)-LN(G26))/(2*$K$5) -> 0.044094154
B27: Rayon | C27: =GEOMEAN(D27,E27) -> 24.559331 | D27: 21.922321 | E27: 27.513544 | F27: =GEOMEAN(G27:H27) -> 7.7877128e-13 | G27: =(D27*0.000001)/(365*24*3600) -> 6.9515223e-13 | H27: =(E27*0.000001)/(365*24*3600) -> 8.7244877e-13 | I27: =LN(F27) -> -27.881059 | J27: =(LN(H27)-LN(G27))/(2*$K$5) -> 0.044094154
B28: Lyocell | C28: =GEOMEAN(D28,E28) -> 39.899771 | D28: 37.799367 | E28: 42.116889 | F28: =GEOMEAN(G28:H28) -> 1.2652134e-12 | G28: =(D28*0.000001)/(365*24*3600) -> 1.1986101e-12 | H28: =(E28*0.000001)/(365*24*3600) -> 1.3355178e-12 | I28: =LN(F28) -> -27.39578 | J28: =(LN(H28)-LN(G28))/(2*$K$5) -> 0.020993104
B29: Modal | C29: =GEOMEAN(D29,E29) -> 51.909814 | D29: 49.834159 | E29: 54.071923 | F29: =GEOMEAN(G29:H29) -> 1.6460494e-12 | G29: =(D29*0.000001)/(365*24*3600) -> 1.5802308e-12 | H29: =(E29*0.000001)/(365*24*3600) -> 1.7146094e-12 | I29: =LN(F29) -> -27.132643 | J29: =(LN(H29)-LN(G29))/(2*$K$5) -> 0.015841305

Sheet 1.2.SSDR_sediment
B2: SSDR sediment
B4: SSDR values are taken from Louvet et al. (2026), Saadi et al. (2025), Saadi & Boulay (2026), and Corella-Puertas et al. (2023). SBoo requires [m/s] as an input for Kssdr. It is assumed that SSDRs are log-normally distributed (Corella-Puertas et al., 2023), and that the lower to upper limit represents the 99% confidence interval (CI), from which the distribution parameters are derived and used as an input in SBoo (for probabilistic solver). However, when plasticFADE model empirical degradation constants (and their CI) are available, they are used as input to compute degradation rates, ignoring the values below.
I5: log-normal distribution | J5: z_0.995 = | K5: 2.576
B6: Polymer type | C6: Geometric mean SSDR [µm/year] | D6: Lower limit SSDR [µm/year] | E6: Upper limit SSDR [µm/year] | F6: Geometric mean SSDR [m/s] | G6: Lower limit SSDR [m/s] | H6: Upper limit SSDR [m/s] | I6: mu | J6: sigma
B7: EPS | C7: =GEOMEAN(D7,E7) -> 0.031622777 | D7: 0.001 | E7: 1 | F7: =GEOMEAN(G7:H7) -> 1.0027517e-15 | G7: =(D7*0.000001)/(365*24*3600) -> 3.1709792e-17 | H7: =(E7*0.000001)/(365*24*3600) -> 3.1709792e-14 | I7: =LN(F7) -> -34.536029 | J7: =(LN(H7)-LN(G7))/(2*$K$5) -> 1.340791
B8: HDPE | C8: =GEOMEAN(D8,E8) -> 0.10954451 | D8: 0.001 | E8: 12 | F8: =GEOMEAN(G8:H8) -> 3.4736337e-15 | G8: =(D8*0.000001)/(365*24*3600) -> 3.1709792e-17 | H8: =(E8*0.000001)/(365*24*3600) -> 3.805175e-13 | I8: =LN(F8) -> -33.293575 | J8: =(LN(H8)-LN(G8))/(2*$K$5) -> 1.8231098
B9: LDPE | C9: =GEOMEAN(D9,E9) -> 0.70413067 | D9: 0.67 | E9: 0.74 | F9: =GEOMEAN(G9:H9) -> 2.2327837e-14 | G9: =(D9*0.000001)/(365*24*3600) -> 2.1245561e-14 | H9: =(E9*0.000001)/(365*24*3600) -> 2.3465246e-14 | I9: =LN(F9) -> -31.432942 | J9: =(LN(H9)-LN(G9))/(2*$K$5) -> 0.019288135
B10: PA_Nylon | C10: =GEOMEAN(D10,E10) -> 3.2 | D10: 0.032 | E10: 320 | F10: =GEOMEAN(G10:H10) -> 1.0147133e-13 | G10: =(D10*0.000001)/(365*24*3600) -> 1.0147133e-15 | H10: =(E10*0.000001)/(365*24*3600) -> 1.0147133e-11 | I10: =LN(F10) -> -29.919 | J10: =(LN(H10)-LN(G10))/(2*$K$5) -> 1.7877213
B11: PET | C11: =GEOMEAN(D11,E11) -> 0.32403703 | D11: 0.001 | E11: 105 | F11: =GEOMEAN(G11:H11) -> 1.0275147e-14 | G11: =(D11*0.000001)/(365*24*3600) -> 3.1709792e-17 | H11: =(E11*0.000001)/(365*24*3600) -> 3.3295282e-12 | I11: =LN(F11) -> -32.209048 | J11: =(LN(H11)-LN(G11))/(2*$K$5) -> 2.2441218
B12: PP | C12: =GEOMEAN(D12,E12) -> 1.2328828 | D12: 0.2 | E12: 7.6 | F12: =GEOMEAN(G12:H12) -> 3.9094457e-14 | G12: =(D12*0.000001)/(365*24*3600) -> 6.3419584e-15 | H12: =(E12*0.000001)/(365*24*3600) -> 2.4099442e-13 | I12: =LN(F12) -> -30.872796 | J12: =(LN(H12)-LN(G12))/(2*$K$5) -> 0.70605321
B13: PS | C13: =GEOMEAN(D13,E13) -> 0.031622777 | D13: 0.001 | E13: 1 | F13: =GEOMEAN(G13:H13) -> 1.0027517e-15 | G13: =(D13*0.000001)/(365*24*3600) -> 3.1709792e-17 | H13: =(E13*0.000001)/(365*24*3600) -> 3.1709792e-14 | I13: =LN(F13) -> -34.536029 | J13: =(LN(H13)-LN(G13))/(2*$K$5) -> 1.340791
B14: PVC | C14: =GEOMEAN(D14,E14) -> 0.01 | D14: 0.001 | E14: 0.1 | F14: =GEOMEAN(G14:H14) -> 3.1709792e-16 | G14: =(D14*0.000001)/(365*24*3600) -> 3.1709792e-17 | H14: =(E14*0.000001)/(365*24*3600) -> 3.1709792e-15 | I14: =LN(F14) -> -35.687321 | J14: =(LN(H14)-LN(G14))/(2*$K$5) -> 0.89386067
B15: PU | C15: =GEOMEAN(D15,E15) -> 0.25248762 | D15: 0.001 | E15: 63.75 | F15: =GEOMEAN(G15:H15) -> 8.00633e-15 | G15: =(D15*0.000001)/(365*24*3600) -> 3.1709792e-17 | H15: =(E15*0.000001)/(365*24*3600) -> 2.0214992e-12 | I15: =LN(F15) -> -32.458544 | J15: =(LN(H15)-LN(G15))/(2*$K$5) -> 2.1472679
B16: PAN | C16: =GEOMEAN(D16,E16) -> 0.01 | D16: 0.001 | E16: 0.1 | F16: =GEOMEAN(G16:H16) -> 3.1709792e-16 | G16: =(D16*0.000001)/(365*24*3600) -> 3.1709792e-17 | H16: =(E16*0.000001)/(365*24*3600) -> 3.1709792e-15 | I16: =LN(F16) -> -35.687321 | J16: =(LN(H16)-LN(G16))/(2*$K$5) -> 0.89386067
B17: TRWP | C17: - | D17: - | E17: - | F17: =GEOMEAN(G17:H17) -> 3.3287916e-15 | G17: 3.16881e-17 | H17: 3.49685e-13 | I17: =LN(F17) -> -33.336167 | J17: =(LN(H17)-LN(G17))/(2*$K$5) -> 1.8068414
B18: PHA | C18: =GEOMEAN(D18,E18) -> 6.1773214 | D18: 0.23 | E18: 165.91 | F18: =GEOMEAN(G18:H18) -> 1.9588158e-13 | G18: =(D18*0.000001)/(365*24*3600) -> 7.2932522e-15 | H18: =(E18*0.000001)/(365*24*3600) -> 5.2609716e-12 | I18: =LN(F18) -> -29.261266 | J18: =(LN(H18)-LN(G18))/(2*$K$5) -> 1.2773916
B19: PLA | C19: =GEOMEAN(D19,E19) -> 0.08660254 | D19: 0.001 | E19: 7.5 | F19: =GEOMEAN(G19:H19) -> 2.7461485e-15 | G19: =(D19*0.000001)/(365*24*3600) -> 3.1709792e-17 | H19: =(E19*0.000001)/(365*24*3600) -> 2.3782344e-13 | I19: =LN(F19) -> -33.528577 | J19: =(LN(H19)-LN(G19))/(2*$K$5) -> 1.7318824
B20: PCL | C20: =GEOMEAN(D20,E20) -> 14.839903 | D20: 1.31416 | E20: 167.5768 | F20: =GEOMEAN(G20:H20) -> 4.7057024e-13 | G20: =(D20*0.000001)/(365*24*3600) -> 4.167174e-14 | H20: =(E20*0.000001)/(365*24*3600) -> 5.3138255e-12 | I20: =LN(F20) -> -28.384831 | J20: =(LN(H20)-LN(G20))/(2*$K$5) -> 0.94104116
B21: PBSA | C21: =GEOMEAN(D21,E21) -> 1.5655184 | D21: 0.608 | E21: 4.031 | F21: =GEOMEAN(G21:H21) -> 4.9642264e-14 | G21: =(D21*0.000001)/(365*24*3600) -> 1.9279554e-14 | H21: =(E21*0.000001)/(365*24*3600) -> 1.2782217e-13 | I21: =LN(F21) -> -30.633934 | J21: =(LN(H21)-LN(G21))/(2*$K$5) -> 0.36715739
B22: starch_blend | C22: 101.29 | D22: =C22/10 -> 10.129 | E22: =C22*10 -> 1012.9 | F22: =GEOMEAN(G22:H22) -> 3.2118848e-12 | G22: =(D22*0.000001)/(365*24*3600) -> 3.2118848e-13 | H22: =(E22*0.000001)/(365*24*3600) -> 3.2118848e-11 | I22: =LN(F22) -> -26.464163 | J22: =(LN(H22)-LN(G22))/(2*$K$5) -> 0.89386067
B23: PBAT | C23: =GEOMEAN(D23,E23) -> 11.752936 | D23: 10.27 | E23: 13.45 | F23: =GEOMEAN(G23:H23) -> 3.7268315e-13 | G23: =(D23*0.000001)/(365*24*3600) -> 3.2565956e-13 | H23: =(E23*0.000001)/(365*24*3600) -> 4.264967e-13 | I23: =LN(F23) -> -28.618048 | J23: =(LN(H23)-LN(G23))/(2*$K$5) -> 0.052358712
B24: Cotton | C24: =GEOMEAN(D24,E24) -> 18.300786 | D24: 5.9971847 | E24: 55.845997 | F24: =GEOMEAN(G24:H24) -> 5.8031411e-13 | G24: =(D24*0.000001)/(365*24*3600) -> 1.9016948e-13 | H24: =(E24*0.000001)/(365*24*3600) -> 1.770865e-12 | I24: =LN(F24) -> -28.175207 | J24: =(LN(H24)-LN(G24))/(2*$K$5) -> 0.43309544
B25: Linen | C25: =GEOMEAN(D25,E25) -> 32.689902 | D25: 21.74 | E25: 49.155 | F25: =GEOMEAN(G25:H25) -> 1.03659e-12 | G25: =(D25*0.000001)/(365*24*3600) -> 6.8937088e-13 | H25: =(E25*0.000001)/(365*24*3600) -> 1.5586948e-12 | I25: =LN(F25) -> -27.595085 | J25: =(LN(H25)-LN(G25))/(2*$K$5) -> 0.15835107
B26: Viscose | C26: =GEOMEAN(D26,E26) -> 24.559331 | D26: 21.922321 | E26: 27.513544 | F26: =GEOMEAN(G26:H26) -> 7.7877128e-13 | G26: =(D26*0.000001)/(365*24*3600) -> 6.9515223e-13 | H26: =(E26*0.000001)/(365*24*3600) -> 8.7244877e-13 | I26: =LN(F26) -> -27.881059 | J26: =(LN(H26)-LN(G26))/(2*$K$5) -> 0.044094154
B27: Rayon | C27: =GEOMEAN(D27,E27) -> 24.559331 | D27: 21.922321 | E27: 27.513544 | F27: =GEOMEAN(G27:H27) -> 7.7877128e-13 | G27: =(D27*0.000001)/(365*24*3600) -> 6.9515223e-13 | H27: =(E27*0.000001)/(365*24*3600) -> 8.7244877e-13 | I27: =LN(F27) -> -27.881059 | J27: =(LN(H27)-LN(G27))/(2*$K$5) -> 0.044094154
B28: Lyocell | C28: =GEOMEAN(D28,E28) -> 39.899771 | D28: 37.799367 | E28: 42.116889 | F28: =GEOMEAN(G28:H28) -> 1.2652134e-12 | G28: =(D28*0.000001)/(365*24*3600) -> 1.1986101e-12 | H28: =(E28*0.000001)/(365*24*3600) -> 1.3355178e-12 | I28: =LN(F28) -> -27.39578 | J28: =(LN(H28)-LN(G28))/(2*$K$5) -> 0.020993104
B29: Modal | C29: =GEOMEAN(D29,E29) -> 51.909814 | D29: 49.834159 | E29: 54.071923 | F29: =GEOMEAN(G29:H29) -> 1.6460494e-12 | G29: =(D29*0.000001)/(365*24*3600) -> 1.5802308e-12 | H29: =(E29*0.000001)/(365*24*3600) -> 1.7146094e-12 | I29: =LN(F29) -> -27.132643 | J29: =(LN(H29)-LN(G29))/(2*$K$5) -> 0.015841305

Sheet 1.3.SSDR_soil
B2: SSDR soil
B4: SSDR values are taken from Louvet et al. (2026), Saadi et al. (2025), Saadi & Boulay (2026), and Corella-Puertas et al. (2023). SBoo requires [m/s] as an input for Kssdr. It is assumed that SSDRs are log-normally distributed (Corella-Puertas et al., 2023), and that the lower to upper limit represents the 99% confidence interval (CI), from which the distribution parameters are derived and used as an input in SBoo (for probabilistic solver). However, when plasticFADE model empirical degradation constants (and their CI) are available, they are used as input to compute degradation rates, ignoring the values below.
I5: log-normal distribution | J5: z_0.995 = | K5: 2.576
B6: Polymer type | C6: Geometric mean SSDR [µm/year] | D6: Lower limit SSDR [µm/year] | E6: Upper limit SSDR [µm/year] | F6: Geometric mean SSDR [m/s] | G6: Lower limit SSDR [m/s] | H6: Upper limit SSDR [m/s] | I6: mu | J6: sigma | K6: Note
B7: EPS | C7: =GEOMEAN(D7,E7) -> 0.031622777 | D7: 0.001 | E7: 1 | F7: =GEOMEAN(G7:H7) -> 1.0027517e-15 | G7: =(D7*0.000001)/(365*24*3600) -> 3.1709792e-17 | H7: =(E7*0.000001)/(365*24*3600) -> 3.1709792e-14 | I7: =LN(F7) -> -34.536029 | J7: =(LN(H7)-LN(G7))/(2*$K$5) -> 1.340791
B8: HDPE | C8: =GEOMEAN(D8,E8) -> 1.1401754 | D8: 1 | E8: 1.3 | F8: =GEOMEAN(G8:H8) -> 3.6154726e-14 | G8: =(D8*0.000001)/(365*24*3600) -> 3.1709792e-14 | H8: =(E8*0.000001)/(365*24*3600) -> 4.122273e-14 | I8: =LN(F8) -> -30.950969 | J8: =(LN(H8)-LN(G8))/(2*$K$5) -> 0.050924741
B9: LDPE | C9: =GEOMEAN(D9,E9) -> 15.556349 | D9: 11 | E9: 22 | F9: =GEOMEAN(G9:H9) -> 4.932886e-13 | G9: =(D9*0.000001)/(365*24*3600) -> 3.4880771e-13 | H9: =(E9*0.000001)/(365*24*3600) -> 6.9761542e-13 | I9: =LN(F9) -> -28.337682 | J9: =(LN(H9)-LN(G9))/(2*$K$5) -> 0.13453944
B10: PA_Nylon | C10: =GEOMEAN(D10,E10) -> 3.2 | D10: 0.032 | E10: 320 | F10: =GEOMEAN(G10:H10) -> 1.0147133e-13 | G10: =(D10*0.000001)/(365*24*3600) -> 1.0147133e-15 | H10: =(E10*0.000001)/(365*24*3600) -> 1.0147133e-11 | I10: =LN(F10) -> -29.919 | J10: =(LN(H10)-LN(G10))/(2*$K$5) -> 1.7877213
B11: PET | C11: =GEOMEAN(D11,E11) -> 0.59219929 | D11: 0.21 | E11: 1.67 | F11: =GEOMEAN(G11:H11) -> 1.8778516e-14 | G11: =(D11*0.000001)/(365*24*3600) -> 6.6590563e-15 | H11: =(E11*0.000001)/(365*24*3600) -> 5.2955353e-14 | I11: =LN(F11) -> -31.606063 | J11: =(LN(H11)-LN(G11))/(2*$K$5) -> 0.40245951
B12: PP | C12: =GEOMEAN(D12,E12) -> 0.69107852 | D12: 0.29775984 | E12: 1.603942 | F12: =GEOMEAN(G12:H12) -> 2.1913956e-14 | G12: =(D12*0.000001)/(365*24*3600) -> 9.4419026e-15 | H12: =(E12*0.000001)/(365*24*3600) -> 5.0860667e-14 | I12: =LN(F12) -> -31.451653 | J12: =(LN(H12)-LN(G12))/(2*$K$5) -> 0.32685023
B13: PS | C13: =GEOMEAN(D13,E13) -> 0.031622777 | D13: 0.001 | E13: 1 | F13: =GEOMEAN(G13:H13) -> 1.0027517e-15 | G13: =(D13*0.000001)/(365*24*3600) -> 3.1709792e-17 | H13: =(E13*0.000001)/(365*24*3600) -> 3.1709792e-14 | I13: =LN(F13) -> -34.536029 | J13: =(LN(H13)-LN(G13))/(2*$K$5) -> 1.340791
B14: PVC | C14: =GEOMEAN(D14,E14) -> 0.01 | D14: 0.001 | E14: 0.1 | F14: =GEOMEAN(G14:H14) -> 3.1709792e-16 | G14: =(D14*0.000001)/(365*24*3600) -> 3.1709792e-17 | H14: =(E14*0.000001)/(365*24*3600) -> 3.1709792e-15 | I14: =LN(F14) -> -35.687321 | J14: =(LN(H14)-LN(G14))/(2*$K$5) -> 0.89386067
B15: PU | C15: =GEOMEAN(D15,E15) -> 0.25248762 | D15: 0.001 | E15: 63.75 | F15: =GEOMEAN(G15:H15) -> 8.00633e-15 | G15: =(D15*0.000001)/(365*24*3600) -> 3.1709792e-17 | H15: =(E15*0.000001)/(365*24*3600) -> 2.0214992e-12 | I15: =LN(F15) -> -32.458544 | J15: =(LN(H15)-LN(G15))/(2*$K$5) -> 2.1472679
B16: PAN | C16: =GEOMEAN(D16,E16) -> 0.01 | D16: 0.001 | E16: 0.1 | F16: =GEOMEAN(G16:H16) -> 3.1709792e-16 | G16: =(D16*0.000001)/(365*24*3600) -> 3.1709792e-17 | H16: =(E16*0.000001)/(365*24*3600) -> 3.1709792e-15 | I16: =LN(F16) -> -35.687321 | J16: =(LN(H16)-LN(G16))/(2*$K$5) -> 0.89386067
B17: TRWP | C17: - | D17: - | E17: - | F17: =GEOMEAN(G17:H17) -> 2.6740142e-13 | G17: 6.15047e-14 | H17: 1.16257e-12 | I17: =LN(F17) -> -28.950025 | J17: =(LN(H17)-LN(G17))/(2*$K$5) -> 0.5705114
B18: PHA | C18: =GEOMEAN(D18,E18) -> 1194.7446 | D18: 912.5 | E18: 1564.29 | F18: =GEOMEAN(G18:H18) -> 3.7885102e-11 | G18: =(D18*0.000001)/(365*24*3600) -> 2.8935185e-11 | H18: =(E18*0.000001)/(365*24*3600) -> 4.9603311e-11 | I18: =LN(F18) -> -23.996463 | J18: =(LN(H18)-LN(G18))/(2*$K$5) -> 0.10461942
B19: PLA | C19: =GEOMEAN(D19,E19) -> 121.05227 | D19: 78.69 | E19: 186.22 | F19: =GEOMEAN(G19:H19) -> 3.8385423e-12 | G19: =(D19*0.000001)/(365*24*3600) -> 2.4952435e-12 | H19: =(E19*0.000001)/(365*24*3600) -> 5.9049975e-12 | I19: =LN(F19) -> -26.285928 | J19: =(LN(H19)-LN(G19))/(2*$K$5) -> 0.16719967
B20: PCL | C20: =GEOMEAN(D20,E20) -> 14.839903 | D20: 1.31416 | E20: 167.5768 | F20: =GEOMEAN(G20:H20) -> 4.7057024e-13 | G20: =(D20*0.000001)/(365*24*3600) -> 4.167174e-14 | H20: =(E20*0.000001)/(365*24*3600) -> 5.3138255e-12 | I20: =LN(F20) -> -28.384831 | J20: =(LN(H20)-LN(G20))/(2*$K$5) -> 0.94104116
B21: PBSA | C21: =GEOMEAN(D21,E21) -> 44.72287 | D21: 39.673913 | E21: 50.414365 | F21: =GEOMEAN(G21:H21) -> 1.4181529e-12 | G21: =(D21*0.000001)/(365*24*3600) -> 1.2580515e-12 | H21: =(E21*0.000001)/(365*24*3600) -> 1.598629e-12 | I21: =LN(F21) -> -27.281666 | J21: =(LN(H21)-LN(G21))/(2*$K$5) -> 0.046502771
B22: starch_blend | C22: 101.29 | D22: 42.74 | E22: 2556.9 | F22: =GEOMEAN(G22:H22) -> 1.0482564e-11 | G22: =(D22*0.000001)/(365*24*3600) -> 1.3552765e-12 | H22: =(E22*0.000001)/(365*24*3600) -> 8.1078767e-11 | I22: =LN(F22) -> -25.281308 | J22: =(LN(H22)-LN(G22))/(2*$K$5) -> 0.79414123
B23: PBAT | C23: =GEOMEAN(D23,E23) -> 5.4221767 | D23: 1.96 | E23: 15 | F23: =GEOMEAN(G23:H23) -> 1.7193609e-13 | G23: =(D23*0.000001)/(365*24*3600) -> 6.2151192e-14 | H23: =(E23*0.000001)/(365*24*3600) -> 4.7564688e-13 | I23: =LN(F23) -> -29.391654 | J23: =(LN(H23)-LN(G23))/(2*$K$5) -> 0.39501276
B24: Cotton | C24: =GEOMEAN(D24,E24) -> 3.9632422 | D24: =H35 -> 1.8766595 | E24: =H36 -> 8.3698127 | F24: =GEOMEAN(G24:H24) -> 1.2567359e-13 | G24: =(D24*0.000001)/(365*24*3600) -> 5.9508483e-14 | H24: =(E24*0.000001)/(365*24*3600) -> 2.6540502e-13 | I24: =LN(F24) -> -29.705088 | J24: =(LN(H24)-LN(G24))/(2*$K$5) -> 0.29020539
B25: Linen | C25: =GEOMEAN(D25,E25) -> 3.9632422 | D25: =D24 -> 1.8766595 | E25: =E24 -> 8.3698127 | F25: =GEOMEAN(G25:H25) -> 1.2567359e-13 | G25: =(D25*0.000001)/(365*24*3600) -> 5.9508483e-14 | H25: =(E25*0.000001)/(365*24*3600) -> 2.6540502e-13 | I25: =LN(F25) -> -29.705088 | J25: =(LN(H25)-LN(G25))/(2*$K$5) -> 0.29020539 | K25: No degradation data in soil available. The SSDR of cotton was chosen as a proxy, given their common cellulosic composition
B26: Viscose | C26: =GEOMEAN(D26,E26) -> 3.9632422 | D26: =D25 -> 1.8766595 | E26: =E25 -> 8.3698127 | F26: =GEOMEAN(G26:H26) -> 1.2567359e-13 | G26: =(D26*0.000001)/(365*24*3600) -> 5.9508483e-14 | H26: =(E26*0.000001)/(365*24*3600) -> 2.6540502e-13 | I26: =LN(F26) -> -29.705088 | J26: =(LN(H26)-LN(G26))/(2*$K$5) -> 0.29020539
B27: Rayon | C27: =GEOMEAN(D27,E27) -> 3.9632422 | D27: =D26 -> 1.8766595 | E27: =E26 -> 8.3698127 | F27: =GEOMEAN(G27:H27) -> 1.2567359e-13 | G27: =(D27*0.000001)/(365*24*3600) -> 5.9508483e-14 | H27: =(E27*0.000001)/(365*24*3600) -> 2.6540502e-13 | I27: =LN(F27) -> -29.705088 | J27: =(LN(H27)-LN(G27))/(2*$K$5) -> 0.29020539
B28: Lyocell | C28: =GEOMEAN(D28,E28) -> 3.9632422 | D28: =D27 -> 1.8766595 | E28: =E27 -> 8.3698127 | F28: =GEOMEAN(G28:H28) -> 1.2567359e-13 | G28: =(D28*0.000001)/(365*24*3600) -> 5.9508483e-14 | H28: =(E28*0.000001)/(365*24*3600) -> 2.6540502e-13 | I28: =LN(F28) -> -29.705088 | J28: =(LN(H28)-LN(G28))/(2*$K$5) -> 0.29020539
B29: Modal | C29: =GEOMEAN(D29,E29) -> 3.9632422 | D29: =D28 -> 1.8766595 | E29: =E28 -> 8.3698127 | F29: =GEOMEAN(G29:H29) -> 1.2567359e-13 | G29: =(D29*0.000001)/(365*24*3600) -> 5.9508483e-14 | H29: =(E29*0.000001)/(365*24*3600) -> 2.6540502e-13 | I29: =LN(F29) -> -29.705088 | J29: =(LN(H29)-LN(G29))/(2*$K$5) -> 0.29020539
B32: Additional SSDRs are computed, based on the approach of Maga et al. (2022)
B34: Material | C34: Reference | D34: shape factor (1, 2, 3) | E34: % Reduction in mass | F34: time (yr) | G34: Initial size (um) | H34: SSDR (um/yr) | I34: SSDR (m/s)
B35: Cotton | C35: Smith et al. (2021) | D35: 2 | E35: 0.2 | F35: =154/365 -> 0.42191781 | G35: 15 | H35: =1/2*G35/F35*(1-(1-E35)^(1/D35)) -> 1.8766595 | I35: =H35/(365*24*3600)/1000000 -> 5.9508483e-14
B36: Cotton | C36: Smith et al. (2021) | D36: 2 | E36: 0.72 | F36: =154/365 -> 0.42191781 | G36: 15 | H36: =1/2*G36/F36*(1-(1-E36)^(1/D36)) -> 8.3698127 | I36: =H36/(365*24*3600)/1000000 -> 2.6540502e-13
B37: Cotton | C37: Li et al. (2010) | D37: 2 | E37: 0.16 | F37: =90/365 -> 0.24657534 | G37: 15 | H37: =1/2*G37/F37*(1-(1-E37)^(1/D37)) -> 2.5393312 | I37: =H37/(365*24*3600)/1000000 -> 8.0521664e-14
B38: Cotton | C38: Li et al. (2010) | D38: 2 | E38: 0.28 | F38: =90/365 -> 0.24657534 | G38: 15 | H38: =1/2*G38/F38*(1-(1-E38)^(1/D38)) -> 4.6072692 | I38: =H38/(365*24*3600)/1000000 -> 1.4609555e-13

Sheet 1.4.plasticFADE constants
B2: PlasticFADE
B4: plasticFADE empirical constants (deg: x, y, z, tau, theta and eta) are taken from Tang & Boulay (under review). SBoo takes the empirical constants as an input, when available, and combines them with compartment and region specific UV intensity, as well as compartment specific microbial concentration. To derive the uncertainty associated with the degradation model, the mean and standard deviation of plasticFADE are used. The standard deviation defined in plasticFADE corresponds to the std. dev. of normal distribution in log-space, while the fitted value is the mean value from which we take the log.
C6: HDPE | G6: LDPE | K6: PET | O6: PP | S6: PS
B7: Polymer type | C7: Fitted value | D7: Standard deviation | E7: mu | F7: sigma | G7: Fitted value | H7: Standard deviation | I7: mu | J7: sigma | K7: Fitted value | L7: Standard deviation | M7: mu | N7: sigma | O7: Fitted value | P7: Standard deviation | Q7: mu | R7: sigma | S7: Fitted value | T7: Standard deviation | U7: mu | V7: sigma
B8: degx | C8: 0.010262753 | D8: 0.00088522569 | E8: =LN(C8) -> -4.5792341 | F8: =D8 -> 0.00088522569 | G8: 0.01105059 | H8: 0.0057046217 | I8: =LN(G8) -> -4.5052715 | J8: =H8 -> 0.0057046217 | K8: 0.00024327627 | L8: 0.00029524826 | M8: =LN(K8) -> -8.3213129 | N8: =L8 -> 0.00029524826 | O8: 0.0054981915 | P8: 0.0050951617 | Q8: =LN(O8) -> -5.2033361 | R8: =P8 -> 0.0050951617 | S8: 0.00027325415 | T8: 0.00020039698 | U8: =LN(S8) -> -8.2051082 | V8: =T8 -> 0.00020039698
B9: degtau | C9: 3.3584081e-11 | D9: 0.18031552 | E9: =LN(C9) -> -24.116969 | F9: =D9 -> 0.18031552 | G9: 5e-13 | H9: 0.10974721 | I9: =LN(G9) -> -28.324168 | J9: =H9 -> 0.10974721 | K9: 0.79097577 | L9: 0.1933289 | M9: =LN(K9) -> -0.23448794 | N9: =L9 -> 0.1933289 | O9: 0.013720791 | P9: 0.11216725 | Q9: =LN(O9) -> -4.288843 | R9: =P9 -> 0.11216725 | S9: 0.24329239 | T9: 0.067550473 | U9: =LN(S9) -> -1.4134913 | V9: =T9 -> 0.067550473
B10: degy | C10: 0.0021825284 | D10: 0.004283861 | E10: =LN(C10) -> -6.1272713 | F10: =D10 -> 0.004283861 | G10: 0.01031456 | H10: 0.0061122893 | I10: =LN(G10) -> -4.5741988 | J10: =H10 -> 0.0061122893 | K10: 1.3261956e-05 | L10: 2.1960389e-05 | M10: =LN(K10) -> -11.230611 | N10: =L10 -> 2.1960389e-05 | O10: 0.01724523 | P10: 0.0016245855 | Q10: =LN(O10) -> -4.0602197 | R10: =P10 -> 0.0016245855 | S10: 0.014446952 | T10: 4.3872181e-06 | U10: =LN(S10) -> -4.2372718 | V10: =T10 -> 4.3872181e-06
B11: degtheta | C11: 0.29904863 | D11: 0.56576349 | E11: =LN(C11) -> -1.2071491 | F11: =D11 -> 0.56576349 | G11: 0.0043620223 | H11: 3.6211087e-05 | I11: =LN(G11) -> -5.4348195 | J11: =H11 -> 3.6211087e-05 | K11: 1.8763022 | L11: 0.22318783 | M11: =LN(K11) -> 0.62930293 | N11: =L11 -> 0.22318783 | O11: 0.70549282 | P11: 0.3804722 | Q11: =LN(O11) -> -0.34885869 | R11: =P11 -> 0.3804722 | S11: 1.0090732 | T11: 0.16004413 | U11: =LN(S11) -> 0.0090322632 | V11: =T11 -> 0.16004413
B12: degz | C12: 0.00037803206 | D12: 0.0010821863 | E12: =LN(C12) -> -7.8805316 | F12: =D12 -> 0.0010821863 | G12: 0.00010475543 | H12: 0.00044412819 | I12: =LN(G12) -> -9.1638822 | J12: =H12 -> 0.00044412819 | K12: 0.015217891 | L12: 4.4013893e-06 | M12: =LN(K12) -> -4.1852835 | N12: =L12 -> 4.4013893e-06 | O12: 1.6158544e-05 | P12: 3.8147496e-05 | Q12: =LN(O12) -> -11.033062 | R12: =P12 -> 3.8147496e-05 | S12: 6.2330522e-05 | T12: 0.00017657694 | U12: =LN(S12) -> -9.6830593 | V12: =T12 -> 0.00017657694
B13: degeta | C13: 0.21648777 | D13: 0.17415974 | E13: =LN(C13) -> -1.5302212 | F13: =D13 -> 0.17415974 | G13: 0.32405972 | H13: 0.19223313 | I13: =LN(G13) -> -1.1268275 | J13: =H13 -> 0.19223313 | K13: 0.07846195 | L13: 0.045684842 | M13: =LN(K13) -> -2.5451415 | N13: =L13 -> 0.045684842 | O13: 0.44210919 | P13: 0.11138573 | Q13: =LN(O13) -> -0.8161984 | R13: =P13 -> 0.11138573 | S13: 0.49603679 | T13: 0.1221179 | U13: =LN(S13) -> -0.70110518 | V13: =T13 -> 0.1221179

Sheet 1.5.UVintensity
A1: Adjustment factor per region | G1: Global average UV intensity | K1: Region- and compartment-specific UV intensity [W*m-2]
A2: Region | B2: Latitude range [º] | C2: Longitude range [º] | E2: Adjustment factor [-] | G2: Region | H2: Value [W*m-2] | I2: Reference | K2: Compartment | L2: SBoo compartment name | M2: North America | N2: Latin America | O2: Europe | P2: Africa & Middle East | Q2: Central Asia | R2: Southeast Asia | S2: Northern regions | T2: Oceania | U2: Global scale
A3: North America | B3: (15, 75) | C3: (-170, -50) | E3: 0.802 | G3: Default | H3: 10 | I3: Tang & Boulay (under revision) | K3: Air | L3: air | M3: ='1.5.UVintensity'!$H$3*'1.5.UVintensity'!$E$3*'1.5.UVintensity'!E14 -> 8.02 | N3: ='1.5.UVintensity'!$H$3*'1.5.UVintensity'!$E$4*'1.5.UVintensity'!E14 -> 11.78 | O3: ='1.5.UVintensity'!$H$3*'1.5.UVintensity'!$E$5*'1.5.UVintensity'!E14 -> 5.23 | P3: ='1.5.UVintensity'!$H$3*'1.5.UVintensity'!$E$6*'1.5.UVintensity'!E14 -> 13.82 | Q3: ='1.5.UVintensity'!$H$3*'1.5.UVintensity'!$E$7*'1.5.UVintensity'!E14 -> 5.63 | R3: ='1.5.UVintensity'!$H$3*'1.5.UVintensity'!$E$8*'1.5.UVintensity'!E14 -> 13.65 | S3: ='1.5.UVintensity'!$H$3*'1.5.UVintensity'!$E$9*'1.5.UVintensity'!E14 -> 3.64 | T3: ='1.5.UVintensity'!$H$3*'1.5.UVintensity'!$E$10*'1.5.UVintensity'!E14 -> 11.85 | U3: =H3 -> 10
A4: Latin America | B4: (-60, 15) | C4: (-90, -30) | E4: 1.178 | K4: Agricultural soil | L4: agriculturalsoil | M4: ='1.5.UVintensity'!$H$3*'1.5.UVintensity'!$E$3*'1.5.UVintensity'!E15 -> 0 | N4: ='1.5.UVintensity'!$H$3*'1.5.UVintensity'!$E$4*'1.5.UVintensity'!E15 -> 0 | O4: ='1.5.UVintensity'!$H$3*'1.5.UVintensity'!$E$5*'1.5.UVintensity'!E15 -> 0 | P4: ='1.5.UVintensity'!$H$3*'1.5.UVintensity'!$E$6*'1.5.UVintensity'!E15 -> 0 | Q4: ='1.5.UVintensity'!$H$3*'1.5.UVintensity'!$E$7*'1.5.UVintensity'!E15 -> 0 | R4: ='1.5.UVintensity'!$H$3*'1.5.UVintensity'!$E$8*'1.5.UVintensity'!E15 -> 0 | S4: ='1.5.UVintensity'!$H$3*'1.5.UVintensity'!$E$9*'1.5.UVintensity'!E15 -> 0 | T4: ='1.5.UVintensity'!$H$3*'1.5.UVintensity'!$E$10*'1.5.UVintensity'!E15 -> 0 | U4: =AVERAGE(M4:T4) -> 0
A5: Europe | B5: (35, 70) | C5: (40, 140) | E5: 0.523 | G5: Compartment | H5: K_d [m-1] | I5: Reference | K5: Natural soil | L5: naturalsoil | M5: ='1.5.UVintensity'!$H$3*'1.5.UVintensity'!$E$3*'1.5.UVintensity'!E16 -> 0 | N5: ='1.5.UVintensity'!$H$3*'1.5.UVintensity'!$E$4*'1.5.UVintensity'!E16 -> 0 | O5: ='1.5.UVintensity'!$H$3*'1.5.UVintensity'!$E$5*'1.5.UVintensity'!E16 -> 0 | P5: ='1.5.UVintensity'!$H$3*'1.5.UVintensity'!$E$6*'1.5.UVintensity'!E16 -> 0 | Q5: ='1.5.UVintensity'!$H$3*'1.5.UVintensity'!$E$7*'1.5.UVintensity'!E16 -> 0 | R5: ='1.5.UVintensity'!$H$3*'1.5.UVintensity'!$E$8*'1.5.UVintensity'!E16 -> 0 | S5: ='1.5.UVintensity'!$H$3*'1.5.UVintensity'!$E$9*'1.5.UVintensity'!E16 -> 0 | T5: ='1.5.UVintensity'!$H$3*'1.5.UVintensity'!$E$10*'1.5.UVintensity'!E16 -> 0 | U5: =AVERAGE(M5:T5) -> 0
A6: Africa & Middle East | B6: (-35, 35) | C6: (-20, 60) | E6: 1.382 | G6: Freshwater (river) | H6: 10 | I6: Belmont et al. (2007) | K6: Other soil | L6: othersoil | M6: ='1.5.UVintensity'!$H$3*'1.5.UVintensity'!$E$3*'1.5.UVintensity'!E17 -> 0 | N6: ='1.5.UVintensity'!$H$3*'1.5.UVintensity'!$E$4*'1.5.UVintensity'!E17 -> 0 | O6: ='1.5.UVintensity'!$H$3*'1.5.UVintensity'!$E$5*'1.5.UVintensity'!E17 -> 0 | P6: ='1.5.UVintensity'!$H$3*'1.5.UVintensity'!$E$6*'1.5.UVintensity'!E17 -> 0 | Q6: ='1.5.UVintensity'!$H$3*'1.5.UVintensity'!$E$7*'1.5.UVintensity'!E17 -> 0 | R6: ='1.5.UVintensity'!$H$3*'1.5.UVintensity'!$E$8*'1.5.UVintensity'!E17 -> 0 | S6: ='1.5.UVintensity'!$H$3*'1.5.UVintensity'!$E$9*'1.5.UVintensity'!E17 -> 0 | T6: ='1.5.UVintensity'!$H$3*'1.5.UVintensity'!$E$10*'1.5.UVintensity'!E17 -> 0 | U6: =AVERAGE(M6:T6) -> 0
A7: Central Asia | B7: (35, 70) | C7: (40, 140) | E7: 0.563 | G7: Lake | H7: 4 | I7: Morris et al. (1995) | K7: Cloudwater | L7: cloudwater | M7: ='1.5.UVintensity'!$H$3*'1.5.UVintensity'!$E$3*'1.5.UVintensity'!E18 -> 8.02 | N7: ='1.5.UVintensity'!$H$3*'1.5.UVintensity'!$E$4*'1.5.UVintensity'!E18 -> 11.78 | O7: ='1.5.UVintensity'!$H$3*'1.5.UVintensity'!$E$5*'1.5.UVintensity'!E18 -> 5.23 | P7: ='1.5.UVintensity'!$H$3*'1.5.UVintensity'!$E$6*'1.5.UVintensity'!E18 -> 13.82 | Q7: ='1.5.UVintensity'!$H$3*'1.5.UVintensity'!$E$7*'1.5.UVintensity'!E18 -> 5.63 | R7: ='1.5.UVintensity'!$H$3*'1.5.UVintensity'!$E$8*'1.5.UVintensity'!E18 -> 13.65 | S7: ='1.5.UVintensity'!$H$3*'1.5.UVintensity'!$E$9*'1.5.UVintensity'!E18 -> 3.64 | T7: ='1.5.UVintensity'!$H$3*'1.5.UVintensity'!$E$10*'1.5.UVintensity'!E18 -> 11.85 | U7: =H3 -> 10
A8: Southeast Asia | B8: (-10, 35) | C8: (60, 150) | E8: 1.365 | G8: Seawater surface | H8: 0.2 | I8: Llabrés et al. (2010) | K8: Freshwater | L8: river | M8: ='1.5.UVintensity'!$H$3*'1.5.UVintensity'!E3*'1.5.UVintensity'!E19 -> 0.33416667 | N8: ='1.5.UVintensity'!$H$3*'1.5.UVintensity'!E4*'1.5.UVintensity'!E20 -> 0.26772727 | O8: ='1.5.UVintensity'!$H$3*'1.5.UVintensity'!E5*'1.5.UVintensity'!E21 -> 0.27526316 | P8: ='1.5.UVintensity'!$H$3*'1.5.UVintensity'!E6*'1.5.UVintensity'!E22 -> 0.5528 | Q8: ='1.5.UVintensity'!$H$3*'1.5.UVintensity'!E7*'1.5.UVintensity'!E23 -> 0.25590909 | R8: ='1.5.UVintensity'!$H$3*'1.5.UVintensity'!E8*'1.5.UVintensity'!E24 -> 0.41363636 | S8: ='1.5.UVintensity'!$H$3*'1.5.UVintensity'!E9*'1.5.UVintensity'!E25 -> 0.12551724 | T8: ='1.5.UVintensity'!$H$3*'1.5.UVintensity'!E10*'1.5.UVintensity'!E26 -> 1.1849462 | U8: =AVERAGE(M8:T8) -> 0.42624575
A9: Northern regions | B9: (70, 90) | C9: (-180, 180) | E9: 0.364 | K9: Freshwater sediment | L9: freshwatersediment | M9: ='1.5.UVintensity'!$H$3*'1.5.UVintensity'!$E$3*'1.5.UVintensity'!E27 -> 0 | N9: ='1.5.UVintensity'!$H$3*'1.5.UVintensity'!$E$4*'1.5.UVintensity'!E27 -> 0 | O9: ='1.5.UVintensity'!$H$3*'1.5.UVintensity'!$E$5*'1.5.UVintensity'!E27 -> 0 | P9: ='1.5.UVintensity'!$H$3*'1.5.UVintensity'!$E$6*'1.5.UVintensity'!E27 -> 0 | Q9: ='1.5.UVintensity'!$H$3*'1.5.UVintensity'!$E$7*'1.5.UVintensity'!E27 -> 0 | R9: ='1.5.UVintensity'!$H$3*'1.5.UVintensity'!$E$8*'1.5.UVintensity'!E27 -> 0 | S9: ='1.5.UVintensity'!$H$3*'1.5.UVintensity'!$E$9*'1.5.UVintensity'!E27 -> 0 | T9: ='1.5.UVintensity'!$H$3*'1.5.UVintensity'!$E$10*'1.5.UVintensity'!E27 -> 0 | U9: =AVERAGE(M9:T9) -> 0
A10: Oceania | B10: (-50, 0) | C10: (110, 180) | E10: 1.185 | K10: Lake | L10: lake | M10: ='1.5.UVintensity'!$H$3*'1.5.UVintensity'!E3*'1.5.UVintensity'!E28 -> 0.067966102 | N10: ='1.5.UVintensity'!$H$3*'1.5.UVintensity'!E4*'1.5.UVintensity'!E29 -> 0.11459144 | O10: ='1.5.UVintensity'!$H$3*'1.5.UVintensity'!E5*'1.5.UVintensity'!E30 -> 0.048605948 | P10: ='1.5.UVintensity'!$H$3*'1.5.UVintensity'!E6*'1.5.UVintensity'!E31 -> 0.029810181 | Q10: ='1.5.UVintensity'!$H$3*'1.5.UVintensity'!E7*'1.5.UVintensity'!E32 -> 0.042522659 | R10: ='1.5.UVintensity'!$H$3*'1.5.UVintensity'!E8*'1.5.UVintensity'!E33 -> 0.19612069 | S10: ='1.5.UVintensity'!$H$3*'1.5.UVintensity'!E9*'1.5.UVintensity'!E34 -> 0.006899166 | T10: ='1.5.UVintensity'!$H$3*'1.5.UVintensity'!E10*'1.5.UVintensity'!E35 -> 0.33664773 | U10: =AVERAGE(M10:T10) -> 0.10539549
K11: Lake sediment | L11: lakesediment | M11: ='1.5.UVintensity'!$H$3*'1.5.UVintensity'!$E$3*'1.5.UVintensity'!E36 -> 0 | N11: ='1.5.UVintensity'!$H$3*'1.5.UVintensity'!$E$4*'1.5.UVintensity'!E36 -> 0 | O11: ='1.5.UVintensity'!$H$3*'1.5.UVintensity'!$E$5*'1.5.UVintensity'!E36 -> 0 | P11: ='1.5.UVintensity'!$H$3*'1.5.UVintensity'!$E$6*'1.5.UVintensity'!E36 -> 0 | Q11: ='1.5.UVintensity'!$H$3*'1.5.UVintensity'!$E$7*'1.5.UVintensity'!E36 -> 0 | R11: ='1.5.UVintensity'!$H$3*'1.5.UVintensity'!$E$8*'1.5.UVintensity'!E36 -> 0 | S11: ='1.5.UVintensity'!$H$3*'1.5.UVintensity'!$E$9*'1.5.UVintensity'!E36 -> 0 | T11: ='1.5.UVintensity'!$H$3*'1.5.UVintensity'!$E$10*'1.5.UVintensity'!E36 -> 0 | U11: =AVERAGE(M11:T11) -> 0
A12: Scaling factor per region & compartment | K12: Seawater surface | L12: sea | M12: ='1.5.UVintensity'!$H$3*'1.5.UVintensity'!E3*'1.5.UVintensity'!E37 -> 3.4673055 | N12: ='1.5.UVintensity'!$H$3*'1.5.UVintensity'!E4*'1.5.UVintensity'!E38 -> 5.0928752 | O12: ='1.5.UVintensity'!$H$3*'1.5.UVintensity'!E5*'1.5.UVintensity'!E39 -> 2.2610982 | P12: ='1.5.UVintensity'!$H$3*'1.5.UVintensity'!E6*'1.5.UVintensity'!E40 -> 5.9748332 | Q12: ='1.5.UVintensity'!$H$3*'1.5.UVintensity'!E7*'1.5.UVintensity'!E41 -> 2.4340312 | R12: ='1.5.UVintensity'!$H$3*'1.5.UVintensity'!E8*'1.5.UVintensity'!E42 -> 5.9013367 | S12: ='1.5.UVintensity'!$H$3*'1.5.UVintensity'!E9*'1.5.UVintensity'!E43 -> 1.5736898 | T12: ='1.5.UVintensity'!$H$3*'1.5.UVintensity'!E10*'1.5.UVintensity'!E44 -> 5.1231384 | U12: =AVERAGE(M12:T12) -> 3.9785385
A13: Compartment | B13: Region | C13: Depth [m] | D13: K_d [m-1] | E13: Scaling factor [%] | K13: Seawater column | L13: deepocean | M13: ='1.5.UVintensity'!$H$3*'1.5.UVintensity'!$E$3*'1.5.UVintensity'!E45 -> 0 | N13: ='1.5.UVintensity'!$H$3*'1.5.UVintensity'!$E$4*'1.5.UVintensity'!E45 -> 0 | O13: ='1.5.UVintensity'!$H$3*'1.5.UVintensity'!$E$5*'1.5.UVintensity'!E45 -> 0 | P13: ='1.5.UVintensity'!$H$3*'1.5.UVintensity'!$E$6*'1.5.UVintensity'!E45 -> 0 | Q13: ='1.5.UVintensity'!$H$3*'1.5.UVintensity'!$E$7*'1.5.UVintensity'!E45 -> 0 | R13: ='1.5.UVintensity'!$H$3*'1.5.UVintensity'!$E$8*'1.5.UVintensity'!E45 -> 0 | S13: ='1.5.UVintensity'!$H$3*'1.5.UVintensity'!$E$9*'1.5.UVintensity'!E45 -> 0 | T13: ='1.5.UVintensity'!$H$3*'1.5.UVintensity'!$E$10*'1.5.UVintensity'!E45 -> 0 | U13: =AVERAGE(M13:T13) -> 0
A14: Air | B14: – | C14: – | D14: – | E14: 1 | K14: Marine sediment | L14: marinesediment | M14: ='1.5.UVintensity'!$H$3*'1.5.UVintensity'!$E$3*'1.5.UVintensity'!E46 -> 0 | N14: ='1.5.UVintensity'!$H$3*'1.5.UVintensity'!$E$4*'1.5.UVintensity'!E46 -> 0 | O14: ='1.5.UVintensity'!$H$3*'1.5.UVintensity'!$E$5*'1.5.UVintensity'!E46 -> 0 | P14: ='1.5.UVintensity'!$H$3*'1.5.UVintensity'!$E$6*'1.5.UVintensity'!E46 -> 0 | Q14: ='1.5.UVintensity'!$H$3*'1.5.UVintensity'!$E$7*'1.5.UVintensity'!E46 -> 0 | R14: ='1.5.UVintensity'!$H$3*'1.5.UVintensity'!$E$8*'1.5.UVintensity'!E46 -> 0 | S14: ='1.5.UVintensity'!$H$3*'1.5.UVintensity'!$E$9*'1.5.UVintensity'!E46 -> 0 | T14: ='1.5.UVintensity'!$H$3*'1.5.UVintensity'!$E$10*'1.5.UVintensity'!E46 -> 0 | U14: =AVERAGE(M14:T14) -> 0
A15: Agricultural soil | B15: – | C15: – | D15: – | E15: 0
A16: Natural soil | B16: – | C16: – | D16: – | E16: 0
A17: Other soil | B17: – | C17: – | D17: – | E17: 0
A18: Cloudwater | B18: – | C18: – | D18: – | E18: 1
A19: Freshwater | B19: North America | C19: 2.4 | D19: =$H$6 -> 10 | E19: =(1-EXP(-D19*C19))/(D19*C19) -> 0.041666667
B20: Latin America | C20: 4.4 | D20: =$H$6 -> 10 | E20: =(1-EXP(-D20*C20))/(D20*C20) -> 0.022727273
B21: Europe | C21: 1.9 | D21: =$H$6 -> 10 | E21: =(1-EXP(-D21*C21))/(D21*C21) -> 0.052631579
B22: Africa & Middle East | C22: 2.5 | D22: =$H$6 -> 10 | E22: =(1-EXP(-D22*C22))/(D22*C22) -> 0.04
B23: Central Asia | C23: 2.2 | D23: =$H$6 -> 10 | E23: =(1-EXP(-D23*C23))/(D23*C23) -> 0.045454545
B24: Southeast Asia | C24: 3.3 | D24: =$H$6 -> 10 | E24: =(1-EXP(-D24*C24))/(D24*C24) -> 0.03030303
B25: Northern regions | C25: 2.9 | D25: =$H$6 -> 10 | E25: =(1-EXP(-D25*C25))/(D25*C25) -> 0.034482759
B26: Oceania | C26: 1 | D26: =$H$6 -> 10 | E26: =(1-EXP(-D26*C26))/(D26*C26) -> 0.09999546
A27: Freshwater sediment | B27: – | C27: – | D27: – | E27: 0
A28: Lake | B28: North America | C28: 29.5 | D28: =$H$7 -> 4 | E28: =(1-EXP(-D28*C28))/(D28*C28) -> 0.0084745763
B29: Latin America | C29: 25.7 | D29: =$H$7 -> 4 | E29: =(1-EXP(-D29*C29))/(D29*C29) -> 0.0097276265
B30: Europe | C30: 26.9 | D30: =$H$7 -> 4 | E30: =(1-EXP(-D30*C30))/(D30*C30) -> 0.0092936803
B31: Africa & Middle East | C31: 115.9 | D31: =$H$7 -> 4 | E31: =(1-EXP(-D31*C31))/(D31*C31) -> 0.0021570319
B32: Central Asia | C32: 33.1 | D32: =$H$7 -> 4 | E32: =(1-EXP(-D32*C32))/(D32*C32) -> 0.0075528701
B33: Southeast Asia | C33: 17.4 | D33: =$H$7 -> 4 | E33: =(1-EXP(-D33*C33))/(D33*C33) -> 0.014367816
B34: Northern regions | C34: 131.9 | D34: =$H$7 -> 4 | E34: =(1-EXP(-D34*C34))/(D34*C34) -> 0.0018953753
B35: Oceania | C35: 8.8 | D35: =$H$7 -> 4 | E35: =(1-EXP(-D35*C35))/(D35*C35) -> 0.028409091
A36: Lake sediment | B36: – | C36: – | D36: – | E36: 0
A37: Seawater surface | B37: North America | C37: 10 | D37: =$H$8 -> 0.2 | E37: =(1-EXP(-D37*C37))/(D37*C37) -> 0.43233236 | F37: (Carla updating)
B38: Latin America | C38: 10 | D38: =$H$8 -> 0.2 | E38: =(1-EXP(-D38*C38))/(D38*C38) -> 0.43233236 | F38: (Carla updating)
B39: Europe | C39: 10 | D39: =$H$8 -> 0.2 | E39: =(1-EXP(-D39*C39))/(D39*C39) -> 0.43233236 | F39: (Carla updating)
B40: Africa & Middle East | C40: 10 | D40: =$H$8 -> 0.2 | E40: =(1-EXP(-D40*C40))/(D40*C40) -> 0.43233236 | F40: (Carla updating)
...

Sheet 2.1.sed_rates
B2: Default sedimentation rates for low-density polymers
B4: Default sedimentation rates are taken from Corella-Puertas et al. (2023). They are only used when SBoo returns a settling velocity of 0 m/s (for particles with density lower than that of water). For the marine environment, these default settling velocities are not used, as TrackMPD is used to derive settling velocities. TrackMPD value are shown for comparison only.
D5: 100 | E5: m | F5: TrackMPD value (water column) | H5: TrackMPD value (water surface)
B6: polymer type | C6: default sed rate [s-1] | D6: default sed velocity [m.s-1] | F6: 1um | G6: 5000um | H6: 1um | I6: 5000um
B7: EPS | C7: 8.35e-13 | D7: =C7*$D$5 -> 8.35e-11 | E7: m/s | F7: ='2.1.trackMPD'!AC11/(24*60*60) -> 4.7732852e-06 | G7: ='2.1.trackMPD'!AC7/(24*60*60) -> 1.9069435e-05 | H7: ='2.1.trackMPD'!AB11/(24*60*60) -> 6.7421007e-06 | I7: ='2.1.trackMPD'!AB7/(24*60*60) -> 6.1388963e-07
B8: PP | C8: 5.67e-10 | D8: =C8*$D$5 -> 5.67e-08 | E8: m/s | F8: ='2.1.trackMPD'!AC51/(24*60*60) -> 4.5227098e-06 | G8: ='2.1.trackMPD'!AC47/(24*60*60) -> 0.0023915465 | H8: ='2.1.trackMPD'!AB51/(24*60*60) -> 4.5139356e-06 | I8: ='2.1.trackMPD'!AB47/(24*60*60) -> 1.2686836e-06
B9: HDPE | C9: 5.67e-10 | D9: =C9*$D$5 -> 5.67e-08 | E9: m/s | F9: ='2.1.trackMPD'!AC21/(24*60*60) -> 5.7336989e-05 | G9: ='2.1.trackMPD'!AC17/(24*60*60) -> 0.0029897651 | H9: ='2.1.trackMPD'!AB21/(24*60*60) -> 1.3226447e-05 | I9: ='2.1.trackMPD'!AB17/(24*60*60) -> 2.3939741e-06
B10: LDPE | C10: 5.67e-10 | D10: =C10*$D$5 -> 5.67e-08 | E10: m/s | F10: ='2.1.trackMPD'!AC31/(24*60*60) -> 7.4430661e-05 | G10: ='2.1.trackMPD'!AC27/(24*60*60) -> 0.0025636687 | H10: ='2.1.trackMPD'!AB31/(24*60*60) -> 1.1641858e-05 | I10: ='2.1.trackMPD'!AB27/(24*60*60) -> 1.5404144e-06

Sheet 2.1.trackMPD
B2: Settling and transfer rates derived from TrackMPD | E2: TO BE FINALIZED
B4: Regional transfer from water surface to water column, and water column to sediments, at continental and global scale was determine through TrackMPD. Transfer from continental to global water is also derived from TrackMPD. More information can be found in Hajjar et al. (2025) on how the model is parametrized. If a velocity is not available, SBoo will compute it.
A5: a | I5: m/d | J5: m/d | K5: d-1 | L5: d-1 | M5: m/d | N5: m/d | AB5: average in open ocean (m/d)
A6: Region | B6: Country_all | C6: Polymer_all | D6: Density_code | E6: Density_all | F6: Shape_all | G6: Size_all | H6: Diameter_all | I6: v_Surf2Col_cont_median_all | J6: v_Col2Sed_cont_median_all | K6: v_Surf2glo_median_all | L6: v_Col2glo_median_all | M6: v_Surf2Col_glo_median_all | N6: v_Col2Sed_glo_median_all | R6: Polymer | S6: Density | T6: Code | V6: Region | W6: Density_code | X6: Density_all | Y6: Shape_all | Z6: Size_all | AA6: Diameter_all | AB6: v_Surf2Col_glo_median_all | AC6: v_Col2Sed_glo_median_all | AJ6: USEtox continent | AK6: Northern regions | AL6: Central Asia | AM6: Southeast Asia | AO6: Oceania | AP6: Europe | AR6: Africa&Middle east | AU6: North America | AV6: Latin America
A7: Northern regions | B7: KaraSea | C7: EPS | D7: 1 | E7: 0.03 | F7: sphere | G7: 0.005 | H7: 0.005 | I7: 0.048790807 | J7: 0.97546155 | K7: 0 | L7: 0 | M7: 0 | N7: 0 | R7: EPS | S7: 36.5 | T7: 1 | V7: Global | W7: 1 | X7: 0.03 | Y7: sphere | Z7: 0.005 | AA7: 0.005 | AB7: =AVERAGEIFS('2.1.trackMPD'!M:M,'2.1.trackMPD'!D:D,W7,'2.1.trackMPD'!F:F,Y7,'2.1.trackMPD'!H:H,AA7) -> 0.053040064 | AC7: =AVERAGEIFS('2.1.trackMPD'!N:N,'2.1.trackMPD'!D:D,W7,'2.1.trackMPD'!F:F,Y7,'2.1.trackMPD'!H:H,AA7) -> 1.6475992 | AJ7: receiving sea | AK7: Kara sea | AL7: Sea of Okhotsk | AM7: EC-Japan | AN7: Bay of Bengal | AO7: (didnt specify) | AP7: Mediterranean (greece) | AQ7: North sea | AR7: mediterranean (Nile) | AS7: Gulf of Guinea | AT7: Congo | AU7: (didnt specify) | AV7: (didnt specify)
A8: Northern regions | B8: KaraSea | C8: EPS | D8: 1 | E8: 0.03 | F8: sphere | G8: 0.001 | H8: 0.001 | I8: 0.044993512 | J8: 1.165717 | K8: 0 | L8: 0 | M8: 0 | N8: 0 | R8: HDPE | S8: 955 | T8: 4 | V8: Global | W8: 1 | X8: 0.03 | Y8: sphere | Z8: 0.001 | AA8: 0.001 | AB8: =AVERAGEIFS('2.1.trackMPD'!M:M,'2.1.trackMPD'!D:D,W8,'2.1.trackMPD'!F:F,Y8,'2.1.trackMPD'!H:H,AA8) -> 0.13442525 | AC8: =AVERAGEIFS('2.1.trackMPD'!N:N,'2.1.trackMPD'!D:D,W8,'2.1.trackMPD'!F:F,Y8,'2.1.trackMPD'!H:H,AA8) -> 126.60157 | AJ8: Microplastic load Model 1 [tons y-1] (Schmidt et al., 2017) | AK8: 795.54958 | AL8: 38267.5 | AM8: 1469480.8 | AN8: 72844.777 | AO8: 1526.2218 | AP8: 73.158823 | AQ8: 472.68921 | AR8: 84791.834 | AS8: 35195.802 | AT8: 13445.699 | AU8: 572.01341 | AV8: 3729.1249
A9: Northern regions | B9: KaraSea | C9: EPS | D9: 1 | E9: 0.03 | F9: sphere | G9: 0.0001 | H9: 0.0001 | I9: 0.17322306 | J9: 3.4404077 | K9: 0 | L9: 0 | M9: 0 | N9: 0 | R9: LDPE | S9: 925 | T9: 3 | V9: Global | W9: 1 | X9: 0.03 | Y9: sphere | Z9: 0.0001 | AA9: 0.0001 | AB9: =AVERAGEIFS('2.1.trackMPD'!M:M,'2.1.trackMPD'!D:D,W9,'2.1.trackMPD'!F:F,Y9,'2.1.trackMPD'!H:H,AA9) -> 0.89184001 | AC9: =AVERAGEIFS('2.1.trackMPD'!N:N,'2.1.trackMPD'!D:D,W9,'2.1.trackMPD'!F:F,Y9,'2.1.trackMPD'!H:H,AA9) -> 17.543218
A10: Northern regions | B10: KaraSea | C10: EPS | D10: 1 | E10: 0.03 | F10: sphere | G10: 1e-05 | H10: 1e-05 | I10: 0.42721449 | J10: 1.4827506 | K10: 0 | L10: 0 | M10: 0 | N10: 0 | R10: PA_Nylon | S10: 1240 | T10: 6 | V10: Global | W10: 1 | X10: 0.03 | Y10: sphere | Z10: 1e-05 | AA10: 1e-05 | AB10: =AVERAGEIFS('2.1.trackMPD'!M:M,'2.1.trackMPD'!D:D,W10,'2.1.trackMPD'!F:F,Y10,'2.1.trackMPD'!H:H,AA10) -> 0.6308517 | AC10: =AVERAGEIFS('2.1.trackMPD'!N:N,'2.1.trackMPD'!D:D,W10,'2.1.trackMPD'!F:F,Y10,'2.1.trackMPD'!H:H,AA10) -> 5.2478272
A11: Northern regions | B11: KaraSea | C11: EPS | D11: 1 | E11: 0.03 | F11: sphere | G11: 1e-06 | H11: 1e-06 | I11: 0.061039138 | J11: 0.99927459 | K11: 0 | L11: 0 | M11: 0 | N11: 0 | R11: PET | S11: 1350 | T11: 6 | V11: Global | W11: 1 | X11: 0.03 | Y11: sphere | Z11: 1e-06 | AA11: 1e-06 | AB11: =AVERAGEIFS('2.1.trackMPD'!M:M,'2.1.trackMPD'!D:D,W11,'2.1.trackMPD'!F:F,Y11,'2.1.trackMPD'!H:H,AA11) -> 0.5825175 | AC11: =AVERAGEIFS('2.1.trackMPD'!N:N,'2.1.trackMPD'!D:D,W11,'2.1.trackMPD'!F:F,Y11,'2.1.trackMPD'!H:H,AA11) -> 0.41241184
A12: Northern regions | B12: KaraSea | C12: EPS | D12: 1 | E12: 0.03 | F12: fiber | G12: 0.005 | H12: 0.001 | I12: 0.050674625 | J12: 0.97523805 | K12: 0 | L12: 0 | M12: 0 | N12: 0 | R12: PP | S12: 885 | T12: 2 | V12: Global | W12: 1 | X12: 0.03 | Y12: fiber | Z12: 0.005 | AA12: 0.001 | AB12: =AVERAGEIFS('2.1.trackMPD'!M:M,'2.1.trackMPD'!D:D,W12,'2.1.trackMPD'!F:F,Y12,'2.1.trackMPD'!H:H,AA12) -> 0.061415057 | AC12: =AVERAGEIFS('2.1.trackMPD'!N:N,'2.1.trackMPD'!D:D,W12,'2.1.trackMPD'!F:F,Y12,'2.1.trackMPD'!H:H,AA12) -> 56.10675
A13: Northern regions | B13: KaraSea | C13: EPS | D13: 1 | E13: 0.03 | F13: fiber | G13: 0.001 | H13: 0.0001 | I13: 0.10922152 | J13: 2.4484587 | K13: 0 | L13: 0 | M13: 0 | N13: 0 | R13: PS | S13: 1040 | T13: 5 | V13: Global | W13: 1 | X13: 0.03 | Y13: fiber | Z13: 0.001 | AA13: 0.0001 | AB13: =AVERAGEIFS('2.1.trackMPD'!M:M,'2.1.trackMPD'!D:D,W13,'2.1.trackMPD'!F:F,Y13,'2.1.trackMPD'!H:H,AA13) -> 0.38564733 | AC13: =AVERAGEIFS('2.1.trackMPD'!N:N,'2.1.trackMPD'!D:D,W13,'2.1.trackMPD'!F:F,Y13,'2.1.trackMPD'!H:H,AA13) -> 40.095027
A14: Northern regions | B14: KaraSea | C14: EPS | D14: 1 | E14: 0.03 | F14: fiber | G14: 0.0001 | H14: 1e-05 | I14: 0.53087132 | J14: 3.4271453 | K14: 0 | L14: 0 | M14: 0 | N14: 0 | R14: PVC | S14: 1380 | T14: 6 | V14: Global | W14: 1 | X14: 0.03 | Y14: fiber | Z14: 0.0001 | AA14: 1e-05 | AB14: =AVERAGEIFS('2.1.trackMPD'!M:M,'2.1.trackMPD'!D:D,W14,'2.1.trackMPD'!F:F,Y14,'2.1.trackMPD'!H:H,AA14) -> 0.32073267 | AC14: =AVERAGEIFS('2.1.trackMPD'!N:N,'2.1.trackMPD'!D:D,W14,'2.1.trackMPD'!F:F,Y14,'2.1.trackMPD'!H:H,AA14) -> 1.7028413
A15: Northern regions | B15: KaraSea | C15: EPS | D15: 1 | E15: 0.03 | F15: fiber | G15: 5e-05 | H15: 1e-06 | I15: 0.11181453 | J15: 0.98455713 | K15: 0 | L15: 0 | M15: 0 | N15: 0 | R15: PU | S15: 1200 | T15: 5 | V15: Global | W15: 1 | X15: 0.03 | Y15: fiber | Z15: 5e-05 | AA15: 1e-06 | AB15: =AVERAGEIFS('2.1.trackMPD'!M:M,'2.1.trackMPD'!D:D,W15,'2.1.trackMPD'!F:F,Y15,'2.1.trackMPD'!H:H,AA15) -> 0.32923644 | AC15: =AVERAGEIFS('2.1.trackMPD'!N:N,'2.1.trackMPD'!D:D,W15,'2.1.trackMPD'!F:F,Y15,'2.1.trackMPD'!H:H,AA15) -> 0.63879947
A16: Northern regions | B16: KaraSea | C16: EPS | D16: 1 | E16: 0.03 | F16: fiber | G16: 0.025 | H16: 0.005 | I16: 0.047288178 | J16: 0.99707771 | K16: 0 | L16: 0 | M16: 0 | N16: 0 | R16: PAN | S16: 1184 | T16: 5 | V16: Global | W16: 1 | X16: 0.03 | Y16: fiber | Z16: 0.025 | AA16: 0.005 | AB16: =AVERAGEIFS('2.1.trackMPD'!M:M,'2.1.trackMPD'!D:D,W16,'2.1.trackMPD'!F:F,Y16,'2.1.trackMPD'!H:H,AA16) -> 0.43924212 | AC16: =AVERAGEIFS('2.1.trackMPD'!N:N,'2.1.trackMPD'!D:D,W16,'2.1.trackMPD'!F:F,Y16,'2.1.trackMPD'!H:H,AA16) -> 0.71687786
A17: Northern regions | B17: KaraSea | C17: HDPE | D17: 4 | E17: 0.953 | F17: sphere | G17: 0.005 | H17: 0.005 | I17: 0.0446751 | J17: 1.4148403 | K17: 0 | L17: 0 | M17: 0 | N17: 0 | R17: TRWP | S17: 1800 | T17: 6 | V17: Global | W17: 4 | X17: 0.953 | Y17: sphere | Z17: 0.005 | AA17: 0.005 | AB17: =AVERAGEIFS('2.1.trackMPD'!M:M,'2.1.trackMPD'!D:D,W17,'2.1.trackMPD'!F:F,Y17,'2.1.trackMPD'!H:H,AA17) -> 0.20683936 | AC17: =AVERAGEIFS('2.1.trackMPD'!N:N,'2.1.trackMPD'!D:D,W17,'2.1.trackMPD'!F:F,Y17,'2.1.trackMPD'!H:H,AA17) -> 258.31571
A18: Northern regions | B18: KaraSea | C18: HDPE | D18: 4 | E18: 0.953 | F18: sphere | G18: 0.001 | H18: 0.001 | I18: 0.15253466 | J18: 3.4790329 | K18: 0 | L18: 0 | M18: 0 | N18: 0 | R18: PHA | S18: 1220 | T18: 6 | V18: Global | W18: 4 | X18: 0.953 | Y18: sphere | Z18: 0.001 | AA18: 0.001 | AB18: =AVERAGEIFS('2.1.trackMPD'!M:M,'2.1.trackMPD'!D:D,W18,'2.1.trackMPD'!F:F,Y18,'2.1.trackMPD'!H:H,AA18) -> 1.7524517 | AC18: =AVERAGEIFS('2.1.trackMPD'!N:N,'2.1.trackMPD'!D:D,W18,'2.1.trackMPD'!F:F,Y18,'2.1.trackMPD'!H:H,AA18) -> 94.049134
A19: Northern regions | B19: KaraSea | C19: HDPE | D19: 4 | E19: 0.953 | F19: sphere | G19: 0.0001 | H19: 0.0001 | I19: 0.87789609 | J19: 12.3929 | K19: 0 | L19: 0 | M19: 0 | N19: 0 | R19: PLA | S19: 1240 | T19: 6 | V19: Global | W19: 4 | X19: 0.953 | Y19: sphere | Z19: 0.0001 | AA19: 0.0001 | AB19: =AVERAGEIFS('2.1.trackMPD'!M:M,'2.1.trackMPD'!D:D,W19,'2.1.trackMPD'!F:F,Y19,'2.1.trackMPD'!H:H,AA19) -> 0.87736206 | AC19: =AVERAGEIFS('2.1.trackMPD'!N:N,'2.1.trackMPD'!D:D,W19,'2.1.trackMPD'!F:F,Y19,'2.1.trackMPD'!H:H,AA19) -> 12.083765
A20: Northern regions | B20: KaraSea | C20: HDPE | D20: 4 | E20: 0.953 | F20: sphere | G20: 1e-05 | H20: 1e-05 | I20: 0.57103849 | J20: 1.5342524 | K20: 0 | L20: 0 | M20: 0 | N20: 0 | R20: PCL | S20: 1150 | T20: 5 | V20: Global | W20: 4 | X20: 0.953 | Y20: sphere | Z20: 1e-05 | AA20: 1e-05 | AB20: =AVERAGEIFS('2.1.trackMPD'!M:M,'2.1.trackMPD'!D:D,W20,'2.1.trackMPD'!F:F,Y20,'2.1.trackMPD'!H:H,AA20) -> 1.1072854 | AC20: =AVERAGEIFS('2.1.trackMPD'!N:N,'2.1.trackMPD'!D:D,W20,'2.1.trackMPD'!F:F,Y20,'2.1.trackMPD'!H:H,AA20) -> 6.6273913
... A29: Northern regions | B29: KaraSea | C29: LDPE | D29: 3 | E29: 0.915 | F29: sphere | G29: 0.0001 | H29: 0.0001 | I29: 0.67001856 | J29: 10.515711 | K29: 0 | L29: 0 | M29: 0 | N29: 0 | R29: Modal | S29: 1520 | T29: 6 | V29: Global | W29: 3 | X29: 0.915 | Y29: sphere | Z29: 0.0001 | AA29: 0.0001 | AB29: =AVERAGEIFS('2.1.trackMPD'!M:M,'2.1.trackMPD'!D:D,W29,'2.1.trackMPD'!F:F,Y29,'2.1.trackMPD'!H:H,AA29) -> 0.71945823 | AC29: =AVERAGEIFS('2.1.trackMPD'!N:N,'2.1.trackMPD'!D:D,W29,'2.1.trackMPD'!F:F,Y29,'2.1.trackMPD'!H:H,AA29) -> 11.788389
A30: Northern regions | B30: KaraSea | C30: LDPE | D30: 3 | E30: 0.915 | F30: sphere | G30: 1e-05 | H30: 1e-05 | I30: 0.61909204 | J30: 1.5431022 | K30: 0 | L30: 0 | M30: 0 | N30: 0 | V30: Global | W30: 3 | X30: 0.915 | Y30: sphere | Z30: 1e-05 | AA30: 1e-05 | AB30: =AVERAGEIFS('2.1.trackMPD'!M:M,'2.1.trackMPD'!D:D,W30,'2.1.trackMPD'!F:F,Y30,'2.1.trackMPD'!H:H,AA30) -> 1.0438001 | AC30: =AVERAGEIFS('2.1.trackMPD'!N:N,'2.1.trackMPD'!D:D,W30,'2.1.trackMPD'!F:F,Y30,'2.1.trackMPD'!H:H,AA30) -> 7.0612195
A31: Northern regions | B31: KaraSea | C31: LDPE | D31: 3 | E31: 0.915 | F31: sphere | G31: 1e-06 | H31: 1e-06 | I31: 0.058903128 | J31: 0.95410888 | K31: 0 | L31: 0 | M31: 0 | N31: 0 | V31: Global | W31: 3 | X31: 0.915 | Y31: sphere | Z31: 1e-06 | AA31: 1e-06 | AB31: =AVERAGEIFS('2.1.trackMPD'!M:M,'2.1.trackMPD'!D:D,W31,'2.1.trackMPD'!F:F,Y31,'2.1.trackMPD'!H:H,AA31) -> 1.0058565 | AC31: =AVERAGEIFS('2.1.trackMPD'!N:N,'2.1.trackMPD'!D:D,W31,'2.1.trackMPD'!F:F,Y31,'2.1.trackMPD'!H:H,AA31) -> 6.4308091
A32: Northern regions | B32: KaraSea | C32: LDPE | D32: 3 | E32: 0.915 | F32: fiber | G32: 0.005 | H32: 0.001 | I32: 0.072215558 | J32: 1.6948904 | K32: 0 | L32: 0 | M32: 0 | N32: 0 | R32: Density_code | S32: Density | T32: Density | V32: Global | W32: 3 | X32: 0.915 | Y32: fiber | Z32: 0.005 | AA32: 0.001 | AB32: =AVERAGEIFS('2.1.trackMPD'!M:M,'2.1.trackMPD'!D:D,W32,'2.1.trackMPD'!F:F,Y32,'2.1.trackMPD'!H:H,AA32) -> 1.3351858 | AC32: =AVERAGEIFS('2.1.trackMPD'!N:N,'2.1.trackMPD'!D:D,W32,'2.1.trackMPD'!F:F,Y32,'2.1.trackMPD'!H:H,AA32) -> 163.93942
A33: Northern regions | B33: KaraSea | C33: LDPE | D33: 3 | E33: 0.915 | F33: fiber | G33: 0.001 | H33: 0.0001 | I33: 0.46781272 | J33: 12.647985 | K33: 0 | L33: 0 | M33: 0 | N33: 0 | R33: 1 | S33: 0.03 | T33: =S33*1000 -> 30 | V33: Global | W33: 3 | X33: 0.915 | Y33: fiber | Z33: 0.001 | AA33: 0.0001 | AB33: =AVERAGEIFS('2.1.trackMPD'!M:M,'2.1.trackMPD'!D:D,W33,'2.1.trackMPD'!F:F,Y33,'2.1.trackMPD'!H:H,AA33) -> 0.71996929 | AC33: =AVERAGEIFS('2.1.trackMPD'!N:N,'2.1.trackMPD'!D:D,W33,'2.1.trackMPD'!F:F,Y33,'2.1.trackMPD'!H:H,AA33) -> 23.611256
A34: Northern regions | B34: KaraSea | C34: LDPE | D34: 3 | E34: 0.915 | F34: fiber | G34: 0.0001 | H34: 1e-05 | I34: 1.3087316 | J34: 4.0193651 | K34: 0 | L34: 0 | M34: 0 | N34: 0 | R34: 4 | S34: 0.953 | T34: =S34*1000 -> 953 | V34: Global | W34: 3 | X34: 0.915 | Y34: fiber | Z34: 0.0001 | AA34: 1e-05 | AB34: =AVERAGEIFS('2.1.trackMPD'!M:M,'2.1.trackMPD'!D:D,W34,'2.1.trackMPD'!F:F,Y34,'2.1.trackMPD'!H:H,AA34) -> 0.42490207 | AC34: =AVERAGEIFS('2.1.trackMPD'!N:N,'2.1.trackMPD'!D:D,W34,'2.1.trackMPD'!F:F,Y34,'2.1.trackMPD'!H:H,AA34) -> 1.0812044
